Workbook

Sheet 📊 DASHBOARD EJECUTIVO
L1: DATOS GRÁFICOS | N1: Área | O1: Monto
B2: 🏛️ DASHBOARD - GESTIÓN DE PROCESOS EPMGDT | L2: Estado | M2: Cantidad | N2: Dir. Promoción | O2: 1974792
B3: Empresa Pública Metropolitana de Gestión de Destino Turístico - Quito Turismo | L3: Contratado | M3: =COUNTIF('📋 DATOS CONSOLIDADOS'!E:E,"Contratado") -> 8 | N3: Dir. Turismo Neg | O3: 781770
B4: 📅 Fecha de Actualización: 06 de Mayo de 2026 | L4: A Tiempo | M4: =COUNTIF('📋 DATOS CONSOLIDADOS'!E:E,"A Tiempo") -> 23 | N4: Dir. Desarrollo Prod | O4: 331612.46
L5: Con Retraso | M5: =COUNTIF('📋 DATOS CONSOLIDADOS'!E:E,"Con Retraso") -> 27 | N5: DPEI TICS | O5: 284559.93
B6: 📈 INDICADORES CLAVE DE DESEMPEÑO (KPIs) | N6: Dir. Comunicación | O6: 201500
L7: Tipo | M7: Cantidad | N7: Dir. Servicios | O7: 185195.75
B8: TOTAL PROCESOS | C8: PROCESOS PAC | D8: PROCESOS NO PAC | E8: ✅ CONTRATADOS | F8: ✅ A TIEMPO | G8: ⏰ CON RETRASO | H8: 🚫 DESFINANCIADOS | I8: 💰 MONTO TOTAL | J8: 📆 PROM. DÍAS TARDE | L8: PAC | M8: =COUNTIF('📋 DATOS CONSOLIDADOS'!C:C,"PAC") -> 28 | N8: DAF Admin | O8: 169525
B9: =COUNTA('📋 DATOS CONSOLIDADOS'!A:A)-1 -> 58 | C9: =COUNTIF('📋 DATOS CONSOLIDADOS'!C:C,"PAC") -> 28 | D9: =COUNTIF('📋 DATOS CONSOLIDADOS'!C:C,"No PAC") -> 30 | E9: =COUNTIF('📋 DATOS CONSOLIDADOS'!E:E,"Contratado") -> 8 | F9: =COUNTIF('📋 DATOS CONSOLIDADOS'!E:E,"A Tiempo") -> 23 | G9: =COUNTIF('📋 DATOS CONSOLIDADOS'!E:E,"Con Retraso") -> 27 | H9: =COUNTIF('📋 DATOS CONSOLIDADOS'!H:H,"*Desfinanciado*") -> 5 | I9: =SUM('📋 DATOS CONSOLIDADOS'!G:G) -> 6746037.3 | J9: =IFERROR(AVERAGE('📋 DATOS CONSOLIDADOS'!F:F),0) -> 29.777778 | L9: No PAC | M9: =COUNTIF('📋 DATOS CONSOLIDADOS'!C:C,"No PAC") -> 30 | N9: DPEI Estadística | O9: 39246.51
N10: DAF Financiera | O10: 6600
B11: 📊 ANÁLISIS PROCESOS PAC | G11: 📊 ANÁLISIS PROCESOS NO PAC | L11: Tipo | M11: Monto | N11: Dir. Comercialización | O11: 6600
B12: Indicador | C12: Cantidad | D12: Monto | E12: % del Total | G12: Indicador | H12: Cantidad | I12: Monto | J12: % del Total | L12: PAC | M12: =SUMIF('📋 DATOS CONSOLIDADOS'!C:C,"PAC",'📋 DATOS CONSOLIDADOS'!G:G) -> 2765959.7 | N12: DAF RRHH | O12: 676
B13: ✅ Contratado | C13: =COUNTIFS('📋 DATOS CONSOLIDADOS'!C:C,"PAC",'📋 DATOS CONSOLIDADOS'!E:E,"Contratado") -> 2 | D13: =SUMIFS('📋 DATOS CONSOLIDADOS'!G:G,'📋 DATOS CONSOLIDADOS'!C:C,"PAC",'📋 DATOS CONSOLIDADOS'!E:E,"Contratado") -> 297000 | E13: =IFERROR(C13/COUNTIF('📋 DATOS CONSOLIDADOS'!C:C,"PAC"),0) -> 0.071428571 | G13: ✅ Contratado | H13: =COUNTIFS('📋 DATOS CONSOLIDADOS'!C:C,"No PAC",'📋 DATOS CONSOLIDADOS'!E:E,"Contratado") -> 6 | I13: =SUMIFS('📋 DATOS CONSOLIDADOS'!G:G,'📋 DATOS CONSOLIDADOS'!C:C,"No PAC",'📋 DATOS CONSOLIDADOS'!E:E,"Contratado") -> 1107575 | J13: =IFERROR(H13/COUNTIF('📋 DATOS CONSOLIDADOS'!C:C,"No PAC"),0) -> 0.2 | L13: No PAC | M13: =SUMIF('📋 DATOS CONSOLIDADOS'!C:C,"No PAC",'📋 DATOS CONSOLIDADOS'!G:G) -> 1214117.9
B14: ✅ A Tiempo | C14: =COUNTIFS('📋 DATOS CONSOLIDADOS'!C:C,"PAC",'📋 DATOS CONSOLIDADOS'!E:E,"A Tiempo") -> 9 | D14: =SUMIFS('📋 DATOS CONSOLIDADOS'!G:G,'📋 DATOS CONSOLIDADOS'!C:C,"PAC",'📋 DATOS CONSOLIDADOS'!E:E,"En progreso") -> 0 | E14: =IFERROR(C14/COUNTIF('📋 DATOS CONSOLIDADOS'!C:C,"PAC"),0) -> 0.32142857 | G14: ✅ A Tiempo | H14: =COUNTIFS('📋 DATOS CONSOLIDADOS'!C:C,"No PAC",'📋 DATOS CONSOLIDADOS'!E:E,"A Tiempo") -> 14 | I14: =SUMIFS('📋 DATOS CONSOLIDADOS'!G:G,'📋 DATOS CONSOLIDADOS'!C:C,"No PAC",'📋 DATOS CONSOLIDADOS'!E:E,"En progreso") -> 0 | J14: =IFERROR(H14/COUNTIF('📋 DATOS CONSOLIDADOS'!C:C,"No PAC"),0) -> 0.46666667
B15: ⏰ Con Retraso | C15: =COUNTIFS('📋 DATOS CONSOLIDADOS'!C:C,"PAC",'📋 DATOS CONSOLIDADOS'!E:E,"Con Retraso") -> 17 | D15: =SUMIFS('📋 DATOS CONSOLIDADOS'!G:G,'📋 DATOS CONSOLIDADOS'!C:C,"PAC",'📋 DATOS CONSOLIDADOS'!E:E,"Pendiente") -> 0 | E15: =IFERROR(C15/COUNTIF('📋 DATOS CONSOLIDADOS'!C:C,"PAC"),0) -> 0.60714286 | G15: ⏰ Con Retraso | H15: =COUNTIFS('📋 DATOS CONSOLIDADOS'!C:C,"No PAC",'📋 DATOS CONSOLIDADOS'!E:E,"Con Retraso") -> 10 | I15: =SUMIFS('📋 DATOS CONSOLIDADOS'!G:G,'📋 DATOS CONSOLIDADOS'!C:C,"No PAC",'📋 DATOS CONSOLIDADOS'!E:E,"Pendiente") -> 0 | J15: =IFERROR(H15/COUNTIF('📋 DATOS CONSOLIDADOS'!C:C,"No PAC"),0) -> 0.33333333 | L15: Cuatrimestre | M15: Procesos
B16: 📈 TOTAL PAC | C16: =SUM(C13:C15) -> 28 | D16: =SUBTOTAL(9,#REF!) -> #REF! | E16: =SUM(E13:E15) -> 1 | G16: 📈 TOTAL NO PAC | H16: =SUM(H13:H15) -> 30 | I16: =SUM(I13:I15) -> 1107575 | J16: =SUM(J13:J15) -> 1 | L16: Ctm 1 | M16: =C36 -> 23
L17: Ctm 2 | M17: =C37 -> 23
B18: 🏢 RESUMEN POR ÁREA / DIRECCIÓN | L18: Ctm 3 | M18: =C38 -> 12
B19: Área | C19: Total | D19: PAC | E19: No PAC | F19: Contratado | G19: A Tiempo | H19: Con Retraso | I19: Monto Total | J19: Días Tarde Prom
B20: DPEI TICS | C20: =COUNTIF('📋 DATOS CONSOLIDADOS'!A:A,"DPEI TICS") -> 23 | D20: =COUNTIFS('📋 DATOS CONSOLIDADOS'!A:A,"DPEI TICS",'📋 DATOS CONSOLIDADOS'!C:C,"PAC") -> 7 | E20: =COUNTIFS('📋 DATOS CONSOLIDADOS'!A:A,"DPEI TICS",'📋 DATOS CONSOLIDADOS'!C:C,"No PAC") -> 16 | F20: =COUNTIFS('📋 DATOS CONSOLIDADOS'!A:A,"DPEI TICS",'📋 DATOS CONSOLIDADOS'!E:E,"Contratado") -> 0 | G20: =COUNTIFS('📋 DATOS CONSOLIDADOS'!A:A,"DPEI TICS",'📋 DATOS CONSOLIDADOS'!E:E,"A Tiempo") -> 17 | H20: =COUNTIFS('📋 DATOS CONSOLIDADOS'!A:A,"DPEI TICS",'📋 DATOS CONSOLIDADOS'!E:E,"Con Retraso") -> 6 | I20: =SUMIF('📋 DATOS CONSOLIDADOS'!A:A,"DPEI TICS",'📋 DATOS CONSOLIDADOS'!G:G) -> 282559.93 | J20: =IFERROR(AVERAGEIF('📋 DATOS CONSOLIDADOS'!A:A,"DPEI TICS",'📋 DATOS CONSOLIDADOS'!F:F),0) -> 39.5 | L20: Cuatrimestre | M20: A Tiempo | N20: Con Retraso
B21: DPEI Estadística | C21: =COUNTIF('📋 DATOS CONSOLIDADOS'!A:A,"DPEI Estadística") -> 1 | D21: =COUNTIFS('📋 DATOS CONSOLIDADOS'!A:A,"DPEI Estadística",'📋 DATOS CONSOLIDADOS'!C:C,"PAC") -> 1 | E21: =COUNTIFS('📋 DATOS CONSOLIDADOS'!A:A,"DPEI Estadística",'📋 DATOS CONSOLIDADOS'!C:C,"No PAC") -> 0 | F21: =COUNTIFS('📋 DATOS CONSOLIDADOS'!A:A,"DPEI Estadística",'📋 DATOS CONSOLIDADOS'!E:E,"Contratado") -> 0 | G21: =COUNTIFS('📋 DATOS CONSOLIDADOS'!A:A,"DPEI Estadística",'📋 DATOS CONSOLIDADOS'!E:E,"A Tiempo") -> 1 | H21: =COUNTIFS('📋 DATOS CONSOLIDADOS'!A:A,"DPEI Estadística",'📋 DATOS CONSOLIDADOS'!E:E,"Con Retraso") -> 0 | I21: =SUMIF('📋 DATOS CONSOLIDADOS'!A:A,"DPEI Estadística",'📋 DATOS CONSOLIDADOS'!G:G) -> 39246.51 | J21: =IFERROR(AVERAGEIF('📋 DATOS CONSOLIDADOS'!A:A,"DPEI Estadística",'📋 DATOS CONSOLIDADOS'!F:F),0) -> 0 | L21: Ctm 1 | M21: =G36 -> 0 | N21: =H36 -> 16
B22: Dir. Turismo Neg | C22: =COUNTIF('📋 DATOS CONSOLIDADOS'!A:A,"Dir. Turismo Neg") -> 4 | D22: =COUNTIFS('📋 DATOS CONSOLIDADOS'!A:A,"Dir. Turismo Neg",'📋 DATOS CONSOLIDADOS'!C:C,"PAC") -> 3 | E22: =COUNTIFS('📋 DATOS CONSOLIDADOS'!A:A,"Dir. Turismo Neg",'📋 DATOS CONSOLIDADOS'!C:C,"No PAC") -> 1 | F22: =COUNTIFS('📋 DATOS CONSOLIDADOS'!A:A,"Dir. Turismo Neg",'📋 DATOS CONSOLIDADOS'!E:E,"Contratado") -> 2 | G22: =COUNTIFS('📋 DATOS CONSOLIDADOS'!A:A,"Dir. Turismo Neg",'📋 DATOS CONSOLIDADOS'!E:E,"A Tiempo") -> 0 | H22: =COUNTIFS('📋 DATOS CONSOLIDADOS'!A:A,"Dir. Turismo Neg",'📋 DATOS CONSOLIDADOS'!E:E,"Con Retraso") -> 2 | I22: =SUMIF('📋 DATOS CONSOLIDADOS'!A:A,"Dir. Turismo Neg",'📋 DATOS CONSOLIDADOS'!G:G) -> 781770 | J22: =IFERROR(AVERAGEIF('📋 DATOS CONSOLIDADOS'!A:A,"Dir. Turismo Neg",'📋 DATOS CONSOLIDADOS'!F:F),0) -> 48.5 | L22: Ctm 2 | M22: =G37 -> 11 | N22: =H37 -> 11
B23: Dir. Servicios | C23: =COUNTIF('📋 DATOS CONSOLIDADOS'!A:A,"Dir. Servicios") -> 6 | D23: =COUNTIFS('📋 DATOS CONSOLIDADOS'!A:A,"Dir. Servicios",'📋 DATOS CONSOLIDADOS'!C:C,"PAC") -> 4 | E23: =COUNTIFS('📋 DATOS CONSOLIDADOS'!A:A,"Dir. Servicios",'📋 DATOS CONSOLIDADOS'!C:C,"No PAC") -> 2 | F23: =COUNTIFS('📋 DATOS CONSOLIDADOS'!A:A,"Dir. Servicios",'📋 DATOS CONSOLIDADOS'!E:E,"Contratado") -> 0 | G23: =COUNTIFS('📋 DATOS CONSOLIDADOS'!A:A,"Dir. Servicios",'📋 DATOS CONSOLIDADOS'!E:E,"A Tiempo") -> 3 | H23: =COUNTIFS('📋 DATOS CONSOLIDADOS'!A:A,"Dir. Servicios",'📋 DATOS CONSOLIDADOS'!E:E,"Con Retraso") -> 3 | I23: =SUMIF('📋 DATOS CONSOLIDADOS'!A:A,"Dir. Servicios",'📋 DATOS CONSOLIDADOS'!G:G) -> 185195.75 | J23: =IFERROR(AVERAGEIF('📋 DATOS CONSOLIDADOS'!A:A,"Dir. Servicios",'📋 DATOS CONSOLIDADOS'!F:F),0) -> 23 | L23: Ctm 3 | M23: =G38 -> 12 | N23: =H38 -> 0
B24: Dir. Promoción | C24: =COUNTIF('📋 DATOS CONSOLIDADOS'!A:A,"Dir. Promoción") -> 3 | D24: =COUNTIFS('📋 DATOS CONSOLIDADOS'!A:A,"Dir. Promoción",'📋 DATOS CONSOLIDADOS'!C:C,"PAC") -> 2 | E24: =COUNTIFS('📋 DATOS CONSOLIDADOS'!A:A,"Dir. Promoción",'📋 DATOS CONSOLIDADOS'!C:C,"No PAC") -> 1 | F24: =COUNTIFS('📋 DATOS CONSOLIDADOS'!A:A,"Dir. Promoción",'📋 DATOS CONSOLIDADOS'!E:E,"Contratado") -> 1 | G24: =COUNTIFS('📋 DATOS CONSOLIDADOS'!A:A,"Dir. Promoción",'📋 DATOS CONSOLIDADOS'!E:E,"A Tiempo") -> 0 | H24: =COUNTIFS('📋 DATOS CONSOLIDADOS'!A:A,"Dir. Promoción",'📋 DATOS CONSOLIDADOS'!E:E,"Con Retraso") -> 2 | I24: =SUMIF('📋 DATOS CONSOLIDADOS'!A:A,"Dir. Promoción",'📋 DATOS CONSOLIDADOS'!G:G) -> 1974792 | J24: =IFERROR(AVERAGEIF('📋 DATOS CONSOLIDADOS'!A:A,"Dir. Promoción",'📋 DATOS CONSOLIDADOS'!F:F),0) -> 11
B25: Dir. Desarrollo Prod | C25: =COUNTIF('📋 DATOS CONSOLIDADOS'!A:A,"Dir. Desarrollo Prod") -> 2 | D25: =COUNTIFS('📋 DATOS CONSOLIDADOS'!A:A,"Dir. Desarrollo Prod",'📋 DATOS CONSOLIDADOS'!C:C,"PAC") -> 2 | E25: =COUNTIFS('📋 DATOS CONSOLIDADOS'!A:A,"Dir. Desarrollo Prod",'📋 DATOS CONSOLIDADOS'!C:C,"No PAC") -> 0 | F25: =COUNTIFS('📋 DATOS CONSOLIDADOS'!A:A,"Dir. Desarrollo Prod",'📋 DATOS CONSOLIDADOS'!E:E,"Contratado") -> 1 | G25: =COUNTIFS('📋 DATOS CONSOLIDADOS'!A:A,"Dir. Desarrollo Prod",'📋 DATOS CONSOLIDADOS'!E:E,"A Tiempo") -> 0 | H25: =COUNTIFS('📋 DATOS CONSOLIDADOS'!A:A,"Dir. Desarrollo Prod",'📋 DATOS CONSOLIDADOS'!E:E,"Con Retraso") -> 1 | I25: =SUMIF('📋 DATOS CONSOLIDADOS'!A:A,"Dir. Desarrollo Prod",'📋 DATOS CONSOLIDADOS'!G:G) -> 331612.46 | J25: =IFERROR(AVERAGEIF('📋 DATOS CONSOLIDADOS'!A:A,"Dir. Desarrollo Prod",'📋 DATOS CONSOLIDADOS'!F:F),0) -> 1 | L25: Cuatrimestre | M25: Monto
B26: Dir. Comunicación | C26: =COUNTIF('📋 DATOS CONSOLIDADOS'!A:A,"Dir. Comunicación") -> 3 | D26: =COUNTIFS('📋 DATOS CONSOLIDADOS'!A:A,"Dir. Comunicación",'📋 DATOS CONSOLIDADOS'!C:C,"PAC") -> 1 | E26: =COUNTIFS('📋 DATOS CONSOLIDADOS'!A:A,"Dir. Comunicación",'📋 DATOS CONSOLIDADOS'!C:C,"No PAC") -> 2 | F26: =COUNTIFS('📋 DATOS CONSOLIDADOS'!A:A,"Dir. Comunicación",'📋 DATOS CONSOLIDADOS'!E:E,"Contratado") -> 1 | G26: =COUNTIFS('📋 DATOS CONSOLIDADOS'!A:A,"Dir. Comunicación",'📋 DATOS CONSOLIDADOS'!E:E,"A Tiempo") -> 0 | H26: =COUNTIFS('📋 DATOS CONSOLIDADOS'!A:A,"Dir. Comunicación",'📋 DATOS CONSOLIDADOS'!E:E,"Con Retraso") -> 2 | I26: =SUMIF('📋 DATOS CONSOLIDADOS'!A:A,"Dir. Comunicación",'📋 DATOS CONSOLIDADOS'!G:G) -> 201500 | J26: =IFERROR(AVERAGEIF('📋 DATOS CONSOLIDADOS'!A:A,"Dir. Comunicación",'📋 DATOS CONSOLIDADOS'!F:F),0) -> 28.5 | L26: Ctm 1 | M26: =I36 -> 3446107.5
B27: Dir. Comercialización | C27: =COUNTIF('📋 DATOS CONSOLIDADOS'!A:A,"Dir. Comercialización") -> 1 | D27: =COUNTIFS('📋 DATOS CONSOLIDADOS'!A:A,"Dir. Comercialización",'📋 DATOS CONSOLIDADOS'!C:C,"PAC") -> 0 | E27: =COUNTIFS('📋 DATOS CONSOLIDADOS'!A:A,"Dir. Comercialización",'📋 DATOS CONSOLIDADOS'!C:C,"No PAC") -> 1 | F27: =COUNTIFS('📋 DATOS CONSOLIDADOS'!A:A,"Dir. Comercialización",'📋 DATOS CONSOLIDADOS'!E:E,"Contratado") -> 0 | G27: =COUNTIFS('📋 DATOS CONSOLIDADOS'!A:A,"Dir. Comercialización",'📋 DATOS CONSOLIDADOS'!E:E,"A Tiempo") -> 0 | H27: =COUNTIFS('📋 DATOS CONSOLIDADOS'!A:A,"Dir. Comercialización",'📋 DATOS CONSOLIDADOS'!E:E,"Con Retraso") -> 1 | I27: =SUMIF('📋 DATOS CONSOLIDADOS'!A:A,"Dir. Comercialización",'📋 DATOS CONSOLIDADOS'!G:G) -> 6600 | J27: =IFERROR(AVERAGEIF('📋 DATOS CONSOLIDADOS'!A:A,"Dir. Comercialización",'📋 DATOS CONSOLIDADOS'!F:F),0) -> 22 | L27: Ctm 2 | M27: =I37 -> 422494.19
B28: DAF RRHH | C28: =COUNTIF('📋 DATOS CONSOLIDADOS'!A:A,"DAF RRHH") -> 1 | D28: =COUNTIFS('📋 DATOS CONSOLIDADOS'!A:A,"DAF RRHH",'📋 DATOS CONSOLIDADOS'!C:C,"PAC") -> 1 | E28: =COUNTIFS('📋 DATOS CONSOLIDADOS'!A:A,"DAF RRHH",'📋 DATOS CONSOLIDADOS'!C:C,"No PAC") -> 0 | F28: =COUNTIFS('📋 DATOS CONSOLIDADOS'!A:A,"DAF RRHH",'📋 DATOS CONSOLIDADOS'!E:E,"Contratado") -> 0 | G28: =COUNTIFS('📋 DATOS CONSOLIDADOS'!A:A,"DAF RRHH",'📋 DATOS CONSOLIDADOS'!E:E,"A Tiempo") -> 1 | H28: =COUNTIFS('📋 DATOS CONSOLIDADOS'!A:A,"DAF RRHH",'📋 DATOS CONSOLIDADOS'!E:E,"Con Retraso") -> 0 | I28: =SUMIF('📋 DATOS CONSOLIDADOS'!A:A,"DAF RRHH",'📋 DATOS CONSOLIDADOS'!G:G) -> 676 | J28: =IFERROR(AVERAGEIF('📋 DATOS CONSOLIDADOS'!A:A,"DAF RRHH",'📋 DATOS CONSOLIDADOS'!F:F),0) -> 0 | L28: Ctm 3 | M28: =I38 -> 111476
B29: DAF Financiera | C29: =COUNTIF('📋 DATOS CONSOLIDADOS'!A:A,"DAF Financiera") -> 2 | D29: =COUNTIFS('📋 DATOS CONSOLIDADOS'!A:A,"DAF Financiera",'📋 DATOS CONSOLIDADOS'!C:C,"PAC") -> 1 | E29: =COUNTIFS('📋 DATOS CONSOLIDADOS'!A:A,"DAF Financiera",'📋 DATOS CONSOLIDADOS'!C:C,"No PAC") -> 1 | F29: =COUNTIFS('📋 DATOS CONSOLIDADOS'!A:A,"DAF Financiera",'📋 DATOS CONSOLIDADOS'!E:E,"Contratado") -> 0 | G29: =COUNTIFS('📋 DATOS CONSOLIDADOS'!A:A,"DAF Financiera",'📋 DATOS CONSOLIDADOS'!E:E,"A Tiempo") -> 0 | H29: =COUNTIFS('📋 DATOS CONSOLIDADOS'!A:A,"DAF Financiera",'📋 DATOS CONSOLIDADOS'!E:E,"Con Retraso") -> 2 | I29: =SUMIF('📋 DATOS CONSOLIDADOS'!A:A,"DAF Financiera",'📋 DATOS CONSOLIDADOS'!G:G) -> 6600 | J29: =IFERROR(AVERAGEIF('📋 DATOS CONSOLIDADOS'!A:A,"DAF Financiera",'📋 DATOS CONSOLIDADOS'!F:F),0) -> 42.5
B30: DAF Admin | C30: =COUNTIF('📋 DATOS CONSOLIDADOS'!A:A,"DAF Admin") -> 12 | D30: =COUNTIFS('📋 DATOS CONSOLIDADOS'!A:A,"DAF Admin",'📋 DATOS CONSOLIDADOS'!C:C,"PAC") -> 6 | E30: =COUNTIFS('📋 DATOS CONSOLIDADOS'!A:A,"DAF Admin",'📋 DATOS CONSOLIDADOS'!C:C,"No PAC") -> 6 | F30: =COUNTIFS('📋 DATOS CONSOLIDADOS'!A:A,"DAF Admin",'📋 DATOS CONSOLIDADOS'!E:E,"Contratado") -> 3 | G30: =COUNTIFS('📋 DATOS CONSOLIDADOS'!A:A,"DAF Admin",'📋 DATOS CONSOLIDADOS'!E:E,"A Tiempo") -> 1 | H30: =COUNTIFS('📋 DATOS CONSOLIDADOS'!A:A,"DAF Admin",'📋 DATOS CONSOLIDADOS'!E:E,"Con Retraso") -> 8 | I30: =SUMIF('📋 DATOS CONSOLIDADOS'!A:A,"DAF Admin",'📋 DATOS CONSOLIDADOS'!G:G) -> 169525 | J30: =IFERROR(AVERAGEIF('📋 DATOS CONSOLIDADOS'!A:A,"DAF Admin",'📋 DATOS CONSOLIDADOS'!F:F),0) -> 26.75
B31: 📊 TOTALES | C31: =SUM(C20:C30) -> 58 | D31: =SUM(D20:D30) -> 28 | E31: =SUM(E20:E30) -> 30 | F31: =SUM(F20:F30) -> 8 | G31: =SUM(G20:G30) -> 23 | H31: =SUM(H20:H30) -> 27 | I31: =SUM(I20:I30) -> 3980077.6 | J31: =AVERAGE(J20:J30) -> 22.068182
B33: 📅 RESUMEN POR CUATRIMESTRES
B35: Cuatrimestre | C35: Total | D35: PAC | E35: No PAC | F35: Contratado | G35: A Tiempo | H35: Con Retraso | I35: Monto Total | J35: % del Total
B36: 1️⃣ Cuatrimestre 1 (Ene-Abr) | C36: =COUNTIF('📋 DATOS CONSOLIDADOS'!D:D,1) -> 23 | D36: =COUNTIFS('📋 DATOS CONSOLIDADOS'!D:D,1,'📋 DATOS CONSOLIDADOS'!C:C,"PAC") -> 13 | E36: =COUNTIFS('📋 DATOS CONSOLIDADOS'!D:D,1,'📋 DATOS CONSOLIDADOS'!C:C,"No PAC") -> 10 | F36: =COUNTIFS('📋 DATOS CONSOLIDADOS'!D:D,1,'📋 DATOS CONSOLIDADOS'!E:E,"Contratado") -> 7 | G36: =COUNTIFS('📋 DATOS CONSOLIDADOS'!D:D,1,'📋 DATOS CONSOLIDADOS'!E:E,"A Tiempo") -> 0 | H36: =COUNTIFS('📋 DATOS CONSOLIDADOS'!D:D,1,'📋 DATOS CONSOLIDADOS'!E:E,"Con Retraso") -> 16 | I36: =SUMIF('📋 DATOS CONSOLIDADOS'!D:D,1,'📋 DATOS CONSOLIDADOS'!G:G) -> 3446107.5 | J36: =IF(I$39=0,0,I36/I$39) -> 0.86583925
B37: 2️⃣ Cuatrimestre 2 (May-Ago) | C37: =COUNTIF('📋 DATOS CONSOLIDADOS'!D:D,2) -> 23 | D37: =COUNTIFS('📋 DATOS CONSOLIDADOS'!D:D,2,'📋 DATOS CONSOLIDADOS'!C:C,"PAC") -> 11 | E37: =COUNTIFS('📋 DATOS CONSOLIDADOS'!D:D,2,'📋 DATOS CONSOLIDADOS'!C:C,"No PAC") -> 12 | F37: =COUNTIFS('📋 DATOS CONSOLIDADOS'!D:D,2,'📋 DATOS CONSOLIDADOS'!E:E,"Contratado") -> 1 | G37: =COUNTIFS('📋 DATOS CONSOLIDADOS'!D:D,2,'📋 DATOS CONSOLIDADOS'!E:E,"A Tiempo") -> 11 | H37: =COUNTIFS('📋 DATOS CONSOLIDADOS'!D:D,2,'📋 DATOS CONSOLIDADOS'!E:E,"Con Retraso") -> 11 | I37: =SUMIF('📋 DATOS CONSOLIDADOS'!D:D,2,'📋 DATOS CONSOLIDADOS'!G:G) -> 422494.19 | J37: =IF(I$39=0,0,I37/I$39) -> 0.10615225
B38: 3️⃣ Cuatrimestre 3 (Sep-Dic) | C38: =COUNTIF('📋 DATOS CONSOLIDADOS'!D:D,3) -> 12 | D38: =COUNTIFS('📋 DATOS CONSOLIDADOS'!D:D,3,'📋 DATOS CONSOLIDADOS'!C:C,"PAC") -> 4 | E38: =COUNTIFS('📋 DATOS CONSOLIDADOS'!D:D,3,'📋 DATOS CONSOLIDADOS'!C:C,"No PAC") -> 8 | F38: =COUNTIFS('📋 DATOS CONSOLIDADOS'!D:D,3,'📋 DATOS CONSOLIDADOS'!E:E,"Contratado") -> 0 | G38: =COUNTIFS('📋 DATOS CONSOLIDADOS'!D:D,3,'📋 DATOS CONSOLIDADOS'!E:E,"A Tiempo") -> 12 | H38: =COUNTIFS('📋 DATOS CONSOLIDADOS'!D:D,3,'📋 DATOS CONSOLIDADOS'!E:E,"Con Retraso") -> 0 | I38: =SUMIF('📋 DATOS CONSOLIDADOS'!D:D,3,'📋 DATOS CONSOLIDADOS'!G:G) -> 111476 | J38: =IF(I$39=0,0,I38/I$39) -> 0.028008499
B39: 📊 TOTAL ANUAL | C39: =SUM(C36:C38) -> 58 | D39: =SUM(D36:D38) -> 28 | E39: =SUM(E36:E38) -> 30 | F39: =SUM(F36:F38) -> 8 | G39: =SUM(G36:G38) -> 23 | H39: =SUM(H36:H38) -> 27 | I39: =SUM(I36:I38) -> 3980077.6 | J39: =SUM(J36:J38) -> 1
B41: 📉 VISUALIZACIÓN DE INDICADORES
B56: 📈 ANÁLISIS ADICIONAL POR ÁREA
B81: 📖 LEYENDA DE ESTADOS
...

Sheet 📋 DATOS CONSOLIDADOS
A1: Área | B1: Nombre del Proceso | C1: PAC/No PAC | D1: Cuatrimestre | E1: Estado | F1: Días Tarde | G1: Monto | H1: Estado Financiero
A2: DAF Admin | B2: Adquisición de suministros de impresión (toners) | C2: PAC | D2: 2 | E2: Con Retraso | F2: 26 | G2: 18812 | H2: Financiado
A3: DAF Admin | B3: Adquisición suministros de oficina | C3: PAC | D3: 3 | E3: A Tiempo | G3: 10000 | H3: Financiado
A4: DAF Admin | B4: Contratación póliza de seguro bienes | C4: PAC | D4: 1 | E4: Con Retraso | F4: 26 | G4: 39850 | H4: Financiado
A5: DAF Admin | B5: Servicio agencia de viajes - pasajes | C5: No PAC | D5: 1 | E5: Contratado | G5: 9500 | H5: Financiado
A6: DAF Admin | B6: Servicio agencia de viajes - adicional | C6: No PAC | D6: 1 | E6: Contratado | G6: 500 | H6: Financiado
A7: DAF Admin | B7: Servicio fumigación y desratización | C7: No PAC | D7: 1 | E7: Contratado | G7: 1600 | H7: Financiado
A8: DAF Admin | B8: Mantenimiento cámaras de seguridad | C8: No PAC | D8: 1 | E8: Con Retraso | F8: 30 | G8: 1000 | H8: Financiado
A9: DAF Admin | B9: Mantenimiento parque automotor | C9: PAC | D9: 1 | E9: Con Retraso | F9: 14 | G9: 10000 | H9: Financiado
A10: DAF Admin | B10: Mantenimiento de edificios (fase 2) | C10: PAC | D10: 2 | E10: Con Retraso | F10: 30 | G10: 0 | H10: ⚠️ Desfinanciado
A11: DAF Admin | B11: Material de construcción | C11: No PAC | D11: 2 | E11: Con Retraso | F11: 28 | G11: 1000 | H11: Financiado
A12: DAF Admin | B12: Servicio rastreo satelital vehículos | C12: No PAC | D12: 1 | E12: Con Retraso | F12: 30 | G12: 283 | H12: Financiado
A13: DAF Admin | B13: Servicio seguridad y vigilancia 2026-2027 | C13: PAC | D13: 2 | E13: Con Retraso | F13: 30 | G13: 76980 | H13: Financiado
A14: DAF RRHH | B14: Adquisición ropa de trabajo | C14: PAC | D14: 3 | E14: A Tiempo | G14: 676 | H14: Financiado
A15: DAF Financiera | B15: Consultoría auditoría externa | C15: No PAC | D15: 2 | E15: Con Retraso | F15: 27 | G15: 6600 | H15: Financiado
A16: DAF Financiera | B16: Consultoría verificación recaudación Tasa | C16: PAC | D16: 1 | E16: Con Retraso | F16: 58 | G16: 0 | H16: ⚠️ Desfinanciado
A17: Dir. Comercialización | B17: Servicio de Auditoría CCMQ | C17: No PAC | D17: 1 | E17: Con Retraso | F17: 22 | G17: 6600 | H17: Financiado
A18: Dir. Comunicación | B18: Mantenimiento equipos producción audiovisual | C18: No PAC | D18: 2 | E18: Con Retraso | F18: 49 | G18: 3000 | H18: Financiado
A19: Dir. Comunicación | B19: Servicio agencia Publicidad 2026-2027 | C19: PAC | D19: 1 | E19: Con Retraso | F19: 8 | G19: 195000 | H19: Financiado
A20: Dir. Comunicación | B20: Servicio Monitoreo de Medios 2026-2027 | C20: No PAC | D20: 2 | E20: Contratado | G20: 3500 | H20: Financiado
A21: Dir. Desarrollo Prod | B21: Servicio operación Turística press/fam trips | C21: PAC | D21: 1 | E21: Con Retraso | F21: 1 | G21: 184612.46 | H21: Financiado
A22: Dir. Desarrollo Prod | B22: Servicio facilidades Turísticas DMQ | C22: PAC | D22: 1 | E22: Contratado | G22: 147000 | H22: Financiado
A23: Dir. Promoción | B23: Organización eventos promoción turística | C23: PAC | D23: 1 | E23: Con Retraso | F23: 16 | G23: 1357792 | H23: Financiado
A24: Dir. Promoción | B24: Servicio pauta campaña promocional | C24: PAC | D24: 1 | E24: Con Retraso | F24: 6 | G24: 88500 | H24: Financiado
A25: Dir. Promoción | B25: Relaciones públicas Europa 2026-2027 | C25: No PAC | D25: 1 | E25: Contratado | G25: 528500 | H25: Financiado
A26: Dir. Servicios | B26: Asesoría certificaciones internacionales | C26: PAC | D26: 1 | E26: Con Retraso | F26: 22 | G26: 85000 | H26: Financiado
A27: Dir. Servicios | B27: Capacitación Turística DMQ 2026-2027 | C27: PAC | D27: 2 | E27: Con Retraso | F27: 20 | G27: 87195.75 | H27: Financiado
A28: Dir. Servicios | B28: Talleres certificación Competencias | C28: No PAC | D28: 2 | E28: A Tiempo | G28: 9000 | H28: Financiado
A29: Dir. Servicios | B29: Impresión blocks formularios | C29: No PAC | D29: 2 | E29: A Tiempo | G29: 4000 | H29: Financiado
A30: Dir. Servicios | B30: Servicio transporte verificadores | C30: PAC | D30: 2 | E30: Con Retraso | F30: 27 | G30: 0 | H30: ⚠️ Desfinanciado
A31: Dir. Servicios | B31: Consultoría ISO 37001 Antisoborno | C31: PAC | D31: 2 | E31: A Tiempo | G31: 0 | H31: ⚠️ Desfinanciado
A32: Dir. Turismo Neg | B32: Adquisición Material POP | C32: PAC | D32: 1 | E32: Con Retraso | F32: 61 | G32: 27795 | H32: Financiado
A33: Dir. Turismo Neg | B33: Promoción concierto Ed Sheeran | C33: PAC | D33: 1 | E33: Con Retraso | F33: 36 | G33: 40000 | H33: Financiado
A34: Dir. Turismo Neg | B34: Organización evento PCMA 2026 | C34: PAC | D34: 1 | E34: Contratado | G34: 150000 | H34: Financiado
A35: Dir. Turismo Neg | B35: Relaciones públicas América 2026-2027 | C35: No PAC | D35: 1 | E35: Contratado | G35: 563975 | H35: Financiado
A36: DPEI Estadística | B36: Suscripción datos inteligencia Turística | C36: PAC | D36: 2 | E36: A Tiempo | G36: 39246.51 | H36: Financiado
A37: DPEI TICS | B37: Infraestructura tecnológica y respaldos | C37: PAC | D37: 3 | E37: A Tiempo | G37: 42000 | H37: Financiado
A38: DPEI TICS | B38: Adquisición de UPS | C38: PAC | D38: 1 | E38: Con Retraso | F38: 51 | G38: 0 | H38: ⚠️ Desfinanciado
A39: DPEI TICS | B39: Mantenimiento scanner alto rendimiento | C39: PAC | D39: 2 | E39: A Tiempo | G39: 2000 | H39: Financiado
A40: DPEI TICS | B40: Mantenimiento tablets | C40: No PAC | D40: 2 | E40: A Tiempo | G40: 1000 | H40: Financiado
...

Sheet DAF - Jefatura Administrativa
A1: 📊 DAF - JEFATURA ADMINISTRATIVA
A3: INDICADOR | B3: VALOR | D3: ESTADO | E3: CANTIDAD
A4: Total Procesos | B4: =COUNTA(A10:A21) -> 12 | D4: ✅ Contratados | E4: =COUNTIF(D10:D21,"Contratado") -> 3
A5: Procesos PAC | B5: =COUNTIF(B10:B21,"PAC") -> 6 | D5: ✅ A Tiempo | E5: =COUNTIF(D10:D21,"En progreso") -> 0
A6: Procesos No PAC | B6: =COUNTIF(B10:B21,"*No PAC*")+COUNTIF(B10:B21,"NO PAC") -> 12 | D6: ⏰ Con Retraso | E6: =COUNTIF(D10:D21,"Pendiente") -> 0
A7: Monto Total | B7: =SUM(F10:F21) -> 169525 | D7: 🚫 Desfinanciados | E7: =COUNTIF(F10:F21,0) -> 1
A9: Nombre del Proceso | B9: PAC/No PAC | C9: Cuatrimestre | D9: Estado | E9: Días Tarde | F9: Monto
A10: Adquisición de suministros de impresión (toners) para la EPMGDT | B10: PAC | C10: 2 | D10: Con Retraso | E10: 26 | F10: 18812
A11: Adquisición suministros de oficina para la EPMGDT | B11: PAC | C11: 3 | D11: A Tiempo | F11: 10000
A12: Contratación de póliza de seguro para los bienes muebles e inmuebles pertenecientes a la Empresa Pública Metropolitana de Gestión de Destino Turístico | B12: PAC | C12: 1 | D12: Con Retraso | E12: 26 | F12: 39850
A13: Contratación del servicio de agencias de viajes para la provisión de pasajes a�?reos nacionales e internacionales para los servidores de la EPMGDT | B13: No PAC | C13: 1 | D13: Contratado | F13: 9500
A14: Contratación del servicio de agencias de viajes para la provisión de pasajes a�?reos nacionales e internacionales para los servidores de la EPMGDT | B14: No PAC | C14: 1 | D14: Contratado | F14: 500
A15: Contratación del servicio de fumigación y desratización de las instalaciones de la EPMGDT y sus dependencias | B15: NO PAC | C15: 1 | D15: Contratado | F15: 1600
A16: Contratación del servicio de mantenimiento preventivo y correctivo de cámaras de seguridad de la EPMGDT y sus dependencias | B16: NO PAC | C16: 1 | D16: Con Retraso | E16: 30 | F16: 1000
A17: Contratación del servicio de mantenimiento preventivo y correctivo para el parque automotor de la EPMGDT | B17: PAC | C17: 1 | D17: Con Retraso | E17: 14 | F17: 10000
A18: Mantenimiento de edificios de la EPMGDT (fase 2) | B18: PAC | C18: 2 | D18: Con Retraso | E18: 30 | F18: 0
A19: Material de construcción | B19: NO PAC | C19: 2 | D19: Con Retraso | E19: 28 | F19: 1000
A20: Servicio de rastreo satelital para los vehículos y motocicleta de la EPMGDT | B20: NO PAC | C20: 1 | D20: Con Retraso | E20: 30 | F20: 283
A21: Servicio de seguridad y vigilancia para las instalaciones de Quito Turismo y sus Dependencias 2026 - 2027 | B21: PAC | C21: 2 | D21: Con Retraso | E21: 30 | F21: 76980

Sheet DAF - Jefatura de Talento Human
A1: 📊 DAF - TALENTO HUMANO
A3: INDICADOR | B3: VALOR | D3: ESTADO | E3: CANTIDAD
A4: Total Procesos | B4: =COUNTA(A10:A10) -> 1 | D4: ✅ Contratados | E4: =COUNTIF(D10:D10,"Contratado") -> 0
A5: Procesos PAC | B5: =COUNTIF(B10:B10,"PAC") -> 1 | D5: ✅ A Tiempo | E5: 1
A6: Procesos No PAC | B6: =COUNTIF(B10:B10,"*No PAC*")+COUNTIF(B10:B10,"NO PAC") -> 0 | D6: ⏰ Con Retraso | E6: =COUNTIF(D10:D10,"Pendiente") -> 0
A7: Monto Total | B7: =SUM(F10:F10) -> 676 | D7: 🚫 Desfinanciados | E7: =COUNTIF(F10:F10,0) -> 0
A9: Nombre del Proceso | B9: PAC/No PAC | C9: Cuatrimestre | D9: Estado | E9: Días Tarde | F9: Monto
A10: Adquisición de ropa de trabajo para el personal de Código de Trabajo de la EPMGDT | B10: PAC | C10: 3 | D10: A Tiempo | F10: 676

Sheet DAF - Jefatura Financiera
A1: 📊 DAF - JEFATURA FINANCIERA
A3: INDICADOR | B3: VALOR | D3: ESTADO | E3: CANTIDAD
A4: Total Procesos | B4: =COUNTA(A10:A11) -> 2 | D4: ✅ Contratados | E4: =COUNTIF(D10:D11,"Contratado") -> 0
A5: Procesos PAC | B5: =COUNTIF(B10:B11,"PAC") -> 1 | D5: ✅ A Tiempo | E5: =COUNTIF(D10:D11,"En progreso") -> 0
A6: Procesos No PAC | B6: =COUNTIF(B10:B11,"*No PAC*")+COUNTIF(B10:B11,"NO PAC") -> 2 | D6: ⏰ Con Retraso | E6: =COUNTIF(D10:D11,"Pendiente") -> 0
A7: Monto Total | B7: =SUM(F10:F11) -> 6600 | D7: 🚫 Desfinanciados | E7: =COUNTIF(F10:F11,0) -> 1
A9: Nombre del Proceso | B9: PAC/No PAC | C9: Cuatrimestre | D9: Estado | E9: Días Tarde | F9: Monto
A10: Consultoría contratación directa servicio de auditoría externa para los estados financieros del periodo cerrado al 31 de diciembre de 2025 | B10: NO PAC | C10: 2 | D10: Con Retraso | E10: 27 | F10: 6600
A11: Consultoría para la verificación de recaudación de Tasa de Facilidades y Servicios Turísticos 2025. | B11: PAC | C11: 1 | D11: Con Retraso | E11: 58 | F11: 0

Sheet Dirección de Comercialización
A1: 📊 DIRECCIÓN DE COMERCIALIZACIÓN
A3: INDICADOR | B3: VALOR | D3: ESTADO | E3: CANTIDAD
A4: Total Procesos | B4: =COUNTA(A10:A10) -> 1 | D4: ✅ Contratados | E4: =COUNTIF(D10:D10,"Contratado") -> 0
A5: Procesos PAC | B5: =COUNTIF(B10:B10,"PAC") -> 0 | D5: ✅ A Tiempo | E5: =COUNTIF(D10:D10,"En progreso") -> 0
A6: Procesos No PAC | B6: =COUNTIF(B10:B10,"*No PAC*")+COUNTIF(B10:B10,"NO PAC") -> 2 | D6: ⏰ Con Retraso | E6: =COUNTIF(D10:D10,"Pendiente") -> 0
A7: Monto Total | B7: =SUM(F10:F10) -> 6600 | D7: 🚫 Desfinanciados | E7: =COUNTIF(F10:F10,0) -> 0
A9: Nombre del Proceso | B9: PAC/No PAC | C9: Cuatrimestre | D9: Estado | E9: Días Tarde | F9: Monto
A10: Servicio de Auditoría CCMQ | B10: NO PAC | C10: 1 | D10: Con Retraso | E10: 22 | F10: 6600

Sheet Dirección de Comunicación
A1: 📊 DIRECCIÓN DE COMUNICACIÓN
A3: INDICADOR | B3: VALOR | D3: ESTADO | E3: CANTIDAD
A4: Total Procesos | B4: =COUNTA(A10:A12) -> 3 | D4: ✅ Contratados | E4: =COUNTIF(D10:D12,"Contratado") -> 1
A5: Procesos PAC | B5: =COUNTIF(B10:B12,"PAC") -> 1 | D5: ✅ A Tiempo | E5: =COUNTIF(D10:D12,"En progreso") -> 0
A6: Procesos No PAC | B6: =COUNTIF(B10:B12,"*No PAC*")+COUNTIF(B10:B12,"NO PAC") -> 4 | D6: ⏰ Con Retraso | E6: =COUNTIF(D10:D12,"Pendiente") -> 0
A7: Monto Total | B7: =SUM(F10:F12) -> 201500 | D7: 🚫 Desfinanciados | E7: =COUNTIF(F10:F12,0) -> 0
A9: Nombre del Proceso | B9: PAC/No PAC | C9: Cuatrimestre | D9: Estado | E9: Días Tarde | F9: Monto
A10: Gestiónar la contratación para el mantenimiento de equipos para producción audiovisual | B10: NO PAC | C10: 2 | D10: Con Retraso | E10: 49 | F10: 3000
A11: Servicio de agencia de Publicidad especializada en pauta para difundir las acciones de Quito Turismo a nivel nacional, local e internacional 2026 - 2027 | B11: PAC | C11: 1 | D11: Con Retraso | E11: 8 | F11: 195000
A12: Servicio Monitoreo de Medios de Comunicación para Determinar el Impacto de la Información Generada por Quito Servicio de Monitoreo de Información Televisión, Radio, Prensa Turismo 2026 - 2027 | B12: NO PAC | C12: 2 | D12: Contratado | F12: 3500

Sheet Dirección de Desarrollo de Prod
A1: 📊 DIRECCIÓN DE DESARROLLO DE PRODUCTO
A3: INDICADOR | B3: VALOR | D3: ESTADO | E3: CANTIDAD
A4: Total Procesos | B4: =COUNTA(A10:A11) -> 2 | D4: ✅ Contratados | E4: =COUNTIF(D10:D11,"Contratado") -> 1
A5: Procesos PAC | B5: =COUNTIF(B10:B11,"PAC") -> 2 | D5: ✅ A Tiempo | E5: =COUNTIF(D10:D11,"En progreso") -> 0
A6: Procesos No PAC | B6: =COUNTIF(B10:B11,"*No PAC*")+COUNTIF(B10:B11,"NO PAC") -> 0 | D6: ⏰ Con Retraso | E6: =COUNTIF(D10:D11,"Pendiente") -> 0
A7: Monto Total | B7: =SUM(F10:F11) -> 331612.46 | D7: 🚫 Desfinanciados | E7: =COUNTIF(F10:F11,0) -> 0
A9: Nombre del Proceso | B9: PAC/No PAC | C9: Cuatrimestre | D9: Estado | E9: Días Tarde | F9: Monto
A10: Contratación del servicio de operación Turística para los viajes de prensa (press trip), viajes de bloggers (blog trips), familiarización (fam trips), influencers (influencer trip), personalidades, inversionistas, grupos relacionados a la industria de reuniones (turismo de negocios y Atracción de eventos), rutas Turísticas e intercambios de experiencias en el DMQ de los mercados de la industria Turística a nivel local, nacional y mundial para el 2025 y 2026 | B10: PAC | D10: Con Retraso | E10: 1 | F10: 184612.46
A11: Servicio de implementación de facilidades Turísticas en el DMQ | B11: PAC | C11: 1 | D11: Contratado | F11: 147000

Sheet Dirección de Promoción de Desti
A1: 📊 DIRECCIÓN DE PROMOCIÓN DE DESTINO
A3: INDICADOR | B3: VALOR | D3: ESTADO | E3: CANTIDAD
A4: Total Procesos | B4: =COUNTA(A10:A12) -> 3 | D4: ✅ Contratados | E4: =COUNTIF(D10:D12,"Contratado") -> 1
A5: Procesos PAC | B5: =COUNTIF(B10:B12,"PAC") -> 2 | D5: ✅ A Tiempo | E5: =COUNTIF(D10:D12,"En progreso") -> 0
A6: Procesos No PAC | B6: =COUNTIF(B10:B12,"*No PAC*")+COUNTIF(B10:B12,"NO PAC") -> 2 | D6: ⏰ Con Retraso | E6: =COUNTIF(D10:D12,"Pendiente") -> 0
A7: Monto Total | B7: =SUM(F10:F12) -> 1974792 | D7: 🚫 Desfinanciados | E7: =COUNTIF(F10:F12,0) -> 0
A9: Nombre del Proceso | B9: PAC/No PAC | C9: Cuatrimestre | D9: Estado | E9: Días Tarde | F9: Monto
A10: CONTRATACIÓN DEL SERVICIO DE ORGANIZACIÓN DE EVENTOS DE Promoción Turística DEL DESTINO QUITO EN EL MERCADO LOCAL Y NACIONAL PARA LA REALIZACIÓN DE EVENTOS TurísticoS Y GASTRONÓMICOS (PDT) | B10: PAC | C10: 1 | D10: Con Retraso | E10: 16 | F10: 1357792
A11: SERVICIO DE PAUTA DE CAMPAÑA PromociónAL DEL DESTINO QUITO | B11: PAC | C11: 1 | D11: Con Retraso | E11: 6 | F11: 88500
A12: Servicio de relaciones públicas y representación en el exterior para la Promoción del destino Quito para los mercados de Europa y resto del mundo para los años 2026 y 2027 | B12: NO PAC | C12: 1 | D12: Contratado | F12: 528500

Sheet Dirección de Servicios para la 
A1: 📊 DIRECCIÓN DE SERVICIOS
A3: INDICADOR | B3: VALOR | D3: ESTADO | E3: CANTIDAD
A4: Total Procesos | B4: =COUNTA(A10:A15) -> 6 | D4: ✅ Contratados | E4: =COUNTIF(D10:D15,"Contratado") -> 0
A5: Procesos PAC | B5: =COUNTIF(B10:B15,"PAC") -> 4 | D5: ✅ A Tiempo | E5: =COUNTIF(D10:D15,"En progreso") -> 0
A6: Procesos No PAC | B6: =COUNTIF(B10:B15,"*No PAC*")+COUNTIF(B10:B15,"NO PAC") -> 4 | D6: ⏰ Con Retraso | E6: =COUNTIF(D10:D15,"Pendiente") -> 0
A7: Monto Total | B7: =SUM(F10:F15) -> 185195.75 | D7: 🚫 Desfinanciados | E7: =COUNTIF(F10:F15,0) -> 2
A9: Nombre del Proceso | B9: PAC/No PAC | C9: Cuatrimestre | D9: Estado | E9: Días Tarde | F9: Monto
A10: Servicio de Asesoría y asistencia t�?cnica, para la obtención de la certificaciones internacionales en la Gestión de turismo sostenible y calidad del destino | B10: PAC | C10: 1 | D10: Con Retraso | E10: 22 | F10: 85000
A11: Servicio de capacitación Turística para el sector Turístico del Distrito Metropolitano de Quito 2026-2027 | B11: PAC | C11: 2 | D11: Con Retraso | E11: 20 | F11: 87195.75
A12: ServIcio de contratación de talleres y materiales para el proceso de certificación en Competencia Laborales | B12: NO PAC | C12: 2 | D12: A Tiempo | F12: 9000
A13: Servicio de impresión de blocks de formularios aplicados para actividades administrativas desarrolladas por la EPMGDT–Quito Turismo | B13: NO PAC | C13: 2 | D13: A Tiempo | F13: 4000
A14: Servicio de transporte para verificadores | B14: PAC | C14: 2 | D14: Con Retraso | E14: 27 | F14: 0
A15: SERVICIOS DE CONSULTORÍA PARA IMPLEMENTACIÓN DE LA NORMA ISO 37001:2016 SISTEMAS DE Gestión ANTISOBORNO | B15: PAC | C15: 2 | D15: A Tiempo | F15: 0

Sheet Dirección de Turismo de Negocio
A1: 📊 DIRECCIÓN DE TURISMO DE NEGOCIOS
A3: INDICADOR | B3: VALOR | D3: ESTADO | E3: CANTIDAD
A4: Total Procesos | B4: =COUNTA(A10:A13) -> 4 | D4: ✅ Contratados | E4: =COUNTIF(D10:D13,"Contratado") -> 2
A5: Procesos PAC | B5: =COUNTIF(B10:B13,"PAC") -> 3 | D5: ✅ A Tiempo | E5: =COUNTIF(D10:D13,"En progreso") -> 0
A6: Procesos No PAC | B6: =COUNTIF(B10:B13,"*No PAC*")+COUNTIF(B10:B13,"NO PAC") -> 2 | D6: ⏰ Con Retraso | E6: =COUNTIF(D10:D13,"Pendiente") -> 0
A7: Monto Total | B7: =SUM(F10:F13) -> 781770 | D7: 🚫 Desfinanciados | E7: =COUNTIF(F10:F13,0) -> 0
A9: Nombre del Proceso | B9: PAC/No PAC | C9: Cuatrimestre | D9: Estado | E9: Días Tarde | F9: Monto
A10: Adquisición de Material POP | B10: PAC | C10: 1 | D10: Con Retraso | E10: 61 | F10: 27795
A11: Promoción y Posicionamiento Turístico del destino Quito en el marco de la producción del concierto de Ed Sheeran | B11: PAC | C11: 1 | D11: Con Retraso | E11: 36 | F11: 40000
A12: Servicio de Organización y producción de 1 evento internacional captado para 2026 PCMA | B12: PAC | C12: 1 | D12: Contratado | F12: 150000
A13: Servicio de relaciones públicas y representación en el exterior para la Promoción del destino Quito para los mercados de Am�?rica para los años 2026 y 2027 | B13: NO PAC | C13: 1 | D13: Contratado | F13: 563975

Sheet DPEI - Estadística
A1: 📊 DPEI - ESTADÍSTICA
A3: INDICADOR | B3: VALOR | D3: ESTADO | E3: CANTIDAD
A4: Total Procesos | B4: =COUNTA(A10:A10) -> 1 | D4: ✅ Contratados | E4: =COUNTIF(D10:D10,"Contratado") -> 0
A5: Procesos PAC | B5: =COUNTIF(B10:B10,"PAC") -> 1 | D5: ✅ A Tiempo | E5: =COUNTIF(D10:D10,"En progreso") -> 0
A6: Procesos No PAC | B6: =COUNTIF(B10:B10,"*No PAC*")+COUNTIF(B10:B10,"NO PAC") -> 0 | D6: ⏰ Con Retraso | E6: =COUNTIF(D10:D10,"Pendiente") -> 0
A7: Monto Total | B7: =SUM(F10:F10) -> 39246.51 | D7: 🚫 Desfinanciados | E7: =COUNTIF(F10:F10,0) -> 0
A9: Nombre del Proceso | B9: PAC/No PAC | C9: Cuatrimestre | D9: Estado | E9: Días Tarde | F9: Monto
A10: Suscripción al servicio de provisión de datos en línea para la Gestión de servicios de inteligencia Turística | B10: PAC | C10: 2 | D10: A Tiempo | F10: 39246.51

Sheet DPEI - Jefatura de TICS
A1: 📊 DPEI - JEFATURA DE TICS
A3: INDICADOR | B3: VALOR | D3: ESTADO | E3: CANTIDAD
A4: Total Procesos | B4: =COUNTA(A10:A32) -> 23 | D4: ✅ Contratados | E4: =COUNTIF(D10:D32,"Contratado") -> 0
A5: Procesos PAC | B5: =COUNTIF(B10:B32,"PAC") -> 7 | D5: ✅ A Tiempo | E5: =COUNTIF(D10:D32,"En progreso") -> 0
A6: Procesos No PAC | B6: =COUNTIF(B10:B32,"*No PAC*")+COUNTIF(B10:B32,"NO PAC") -> 32 | D6: ⏰ Con Retraso | E6: =COUNTIF(D10:D32,"Pendiente") -> 0
A7: Monto Total | B7: =SUM(F10:F32) -> 282559.93 | D7: 🚫 Desfinanciados | E7: =COUNTIF(F10:F32,0) -> 1
A9: Nombre del Proceso | B9: PAC/No PAC | C9: Cuatrimestre | D9: Estado | E9: Días Tarde | F9: Monto
A10: Adquisición de infraestructura tecnológica y suscripción de herramientas de respaldos y virtualización | B10: PAC | C10: 3 | D10: A Tiempo | F10: 42000
A11: Adquisición de UPS | B11: PAC | C11: 1 | D11: Con Retraso | E11: 51 | F11: 0
A12: Mantenimiento de scanner de alto rendimiento | B12: PAC | C12: 2 | D12: A Tiempo | F12: 2000
A13: Mantenimiento de tablets con vigencia tecnológica | B13: NO PAC | C13: 2 | D13: A Tiempo | F13: 1000
A14: Mantenimiento del ERP Olympo y soporte especializado | B14: PAC | C14: 2 | D14: A Tiempo | F14: 60000
A15: Mantenimiento preventivo de equipos de la solución de networking | B15: NO PAC | C15: 3 | D15: A Tiempo | F15: 3500
A16: Mantenimiento preventivo de la solución de respaldos | B16: NO PAC | C16: 1 | D16: Con Retraso | E16: 65 | F16: 2000
A17: Renovación de hosting | B17: NO PAC | C17: 1 | D17: Con Retraso | E17: 61 | F17: 6600
A18: Renovación de la suscripción de las licencias de diseño asistido por computadoras (cad) diseño gráfico modelado en 3D | B18: NO PAC | C18: 2 | D18: A Tiempo | F18: 7000
A19: Renovación de la suscripción de las licencias de edición de video y diseño gráfico | B19: NO PAC | C19: 3 | D19: A Tiempo | F19: 7200
A20: Renovación de la suscripción de licencia de la herramienta de envió masivo de correos electrónico | B20: NO PAC | C20: 2 | D20: Con Retraso | E20: 26 | F20: 8000
A21: Renovación de licencia de uso del programa geográfica GIS | B21: NO PAC | C21: 2 | D21: A Tiempo | F21: 7000
A22: Renovar y actualizar licencias antivirus | B22: NO PAC | C22: 3 | D22: A Tiempo | F22: 7000
A23: Servicio de datos móviles 2026-2027 | B23: NO PAC | C23: 2 | D23: Con Retraso | E23: 26 | F23: 1400
A24: Servicio de Internet y Enlace de Datos 2026-2027 | B24: PAC | C24: 2 | D24: Con Retraso | E24: 8 | F24: 12500
A25: Servicio de mantenimiento preventivo de computadores con vigencia tecnológica Asus | B25: NO PAC | C25: 3 | D25: A Tiempo | F25: 1000
A26: Servicio de mantenimiento preventivo de computadores con vigencia tecnológica HP | B26: NO PAC | C26: 3 | D26: A Tiempo | F26: 2000
A27: Servicio de mantenimiento preventivo de computadores con vigencia tecnológica MAC | B27: NO PAC | C27: 3 | D27: A Tiempo | F27: 1000
A28: Servicio de mantenimiento preventivo de computadores con vigencia tecnológica SpeedMind | B28: NO PAC | C28: 3 | D28: A Tiempo | F28: 1100
A29: Servicio de mantenimiento preventivo y correctivo de equipos informáticos y tecnológicos (computadores, escaners, proyectores impresoras, y otros) | B29: NO PAC | C29: 3 | D29: A Tiempo | F29: 10000
A30: Suscripción de herramientas de IA para desarrollo de software y Gestión del código fuente | B30: NO PAC | C30: 2 | D30: A Tiempo | F30: 9259.93
A31: Suscripción de herramientas de ofimática colaborativas con correo electrónico, inteligencia de negocios y servicios Cloud | B31: PAC | C31: 2 | D31: A Tiempo | F31: 65000
A32: Suscripción de herramientas de seguridad informática para el aseguramiento de los activos de Información | B32: PAC | C32: 3 | D32: A Tiempo | F32: 26000
